INFO 2025-07-06 13:25:23,426 autoreload 11728 24320 Watching for file changes with StatReloader
INFO 2025-07-06 13:34:23,166 autoreload 9556 24732 Watching for file changes with StatReloader
INFO 2025-07-06 13:37:56,672 autoreload 18092 17920 Watching for file changes with StatReloader
INFO 2025-07-06 13:39:37,645 autoreload 18092 17920 C:\Users\hp\OneDrive\Desktop\Tailwind\Ranjith_Portfolio\Ranjith_Portfolio\settings.py changed, reloading.
INFO 2025-07-06 13:39:40,287 autoreload 24324 9340 Watching for file changes with StatReloader
INFO 2025-07-06 13:42:38,848 autoreload 9220 25408 Watching for file changes with StatReloader
INFO 2025-07-06 13:42:48,648 basehttp 9220 26496 "GET / HTTP/1.1" 200 9552
INFO 2025-07-06 13:42:48,801 basehttp 9220 26496 "GET /static/portfolio/css/style.css HTTP/1.1" 304 0
INFO 2025-07-06 13:42:48,843 basehttp 9220 26496 "GET /static/portfolio/js/main.js HTTP/1.1" 304 0
WARNING 2025-07-06 13:42:54,427 basehttp 9220 26496 "GET /static/portfolio/images/favicon.ico HTTP/1.1" 404 2011
INFO 2025-07-06 13:43:01,927 basehttp 9220 22804 "GET / HTTP/1.1" 200 9552
ERROR 2025-07-06 13:43:23,415 log 9220 15784 Internal Server Error: /admin/portfolio/skill/add/
Traceback (most recent call last):
  File "C:\Users\hp\OneDrive\Desktop\Tailwind\Ranjith_Portfolio\env\Lib\site-packages\django\contrib\sessions\backends\base.py", line 244, in _get_session
    return self._session_cache
           ^^^^^^^^^^^^^^^^^^^
AttributeError: 'SessionStore' object has no attribute '_session_cache'

During handling of the above exception, another exception occurred:

Traceback (most recent call last):
  File "C:\Users\hp\OneDrive\Desktop\Tailwind\Ranjith_Portfolio\env\Lib\site-packages\django\db\backends\utils.py", line 105, in _execute
    return self.cursor.execute(sql, params)
           ~~~~~~~~~~~~~~~~~~~^^^^^^^^^^^^^
  File "C:\Users\hp\OneDrive\Desktop\Tailwind\Ranjith_Portfolio\env\Lib\site-packages\django\db\backends\sqlite3\base.py", line 360, in execute
    return super().execute(query, params)
           ~~~~~~~~~~~~~~~^^^^^^^^^^^^^^^
sqlite3.OperationalError: no such table: django_session

The above exception was the direct cause of the following exception:

Traceback (most recent call last):
  File "C:\Users\hp\OneDrive\Desktop\Tailwind\Ranjith_Portfolio\env\Lib\site-packages\django\core\handlers\exception.py", line 55, in inner
    response = get_response(request)
  File "C:\Users\hp\OneDrive\Desktop\Tailwind\Ranjith_Portfolio\env\Lib\site-packages\django\core\handlers\base.py", line 197, in _get_response
    response = wrapped_callback(request, *callback_args, **callback_kwargs)
  File "C:\Users\hp\OneDrive\Desktop\Tailwind\Ranjith_Portfolio\env\Lib\site-packages\django\contrib\admin\options.py", line 719, in wrapper
    return self.admin_site.admin_view(view)(*args, **kwargs)
           ~~~~~~~~~~~~~~~~~~~~~~~~~~~~~~~~^^^^^^^^^^^^^^^^^
  File "C:\Users\hp\OneDrive\Desktop\Tailwind\Ranjith_Portfolio\env\Lib\site-packages\django\utils\decorators.py", line 192, in _view_wrapper
    result = _process_exception(request, e)
  File "C:\Users\hp\OneDrive\Desktop\Tailwind\Ranjith_Portfolio\env\Lib\site-packages\django\utils\decorators.py", line 190, in _view_wrapper
    response = view_func(request, *args, **kwargs)
  File "C:\Users\hp\OneDrive\Desktop\Tailwind\Ranjith_Portfolio\env\Lib\site-packages\django\views\decorators\cache.py", line 80, in _view_wrapper
    response = view_func(request, *args, **kwargs)
  File "C:\Users\hp\OneDrive\Desktop\Tailwind\Ranjith_Portfolio\env\Lib\site-packages\django\contrib\admin\sites.py", line 234, in inner
    if not self.has_permission(request):
           ~~~~~~~~~~~~~~~~~~~^^^^^^^^^
  File "C:\Users\hp\OneDrive\Desktop\Tailwind\Ranjith_Portfolio\env\Lib\site-packages\django\contrib\admin\sites.py", line 207, in has_permission
    return request.user.is_active and request.user.is_staff
           ^^^^^^^^^^^^^^^^^^^^^^
  File "C:\Users\hp\OneDrive\Desktop\Tailwind\Ranjith_Portfolio\env\Lib\site-packages\django\utils\functional.py", line 251, in inner
    self._setup()
    ~~~~~~~~~~~^^
  File "C:\Users\hp\OneDrive\Desktop\Tailwind\Ranjith_Portfolio\env\Lib\site-packages\django\utils\functional.py", line 404, in _setup
    self._wrapped = self._setupfunc()
                    ~~~~~~~~~~~~~~~^^
  File "C:\Users\hp\OneDrive\Desktop\Tailwind\Ranjith_Portfolio\env\Lib\site-packages\django\contrib\auth\middleware.py", line 40, in <lambda>
    request.user = SimpleLazyObject(lambda: get_user(request))
                                            ~~~~~~~~^^^^^^^^^
  File "C:\Users\hp\OneDrive\Desktop\Tailwind\Ranjith_Portfolio\env\Lib\site-packages\django\contrib\auth\middleware.py", line 20, in get_user
    request._cached_user = auth.get_user(request)
                           ~~~~~~~~~~~~~^^^^^^^^^
  File "C:\Users\hp\OneDrive\Desktop\Tailwind\Ranjith_Portfolio\env\Lib\site-packages\django\contrib\auth\__init__.py", line 304, in get_user
    user_id = _get_user_session_key(request)
  File "C:\Users\hp\OneDrive\Desktop\Tailwind\Ranjith_Portfolio\env\Lib\site-packages\django\contrib\auth\__init__.py", line 95, in _get_user_session_key
    return get_user_model()._meta.pk.to_python(request.session[SESSION_KEY])
                                               ~~~~~~~~~~~~~~~^^^^^^^^^^^^^
  File "C:\Users\hp\OneDrive\Desktop\Tailwind\Ranjith_Portfolio\env\Lib\site-packages\django\contrib\sessions\backends\base.py", line 55, in __getitem__
    return self._session[key]
           ^^^^^^^^^^^^^
  File "C:\Users\hp\OneDrive\Desktop\Tailwind\Ranjith_Portfolio\env\Lib\site-packages\django\contrib\sessions\backends\base.py", line 249, in _get_session
    self._session_cache = self.load()
                          ~~~~~~~~~^^
  File "C:\Users\hp\OneDrive\Desktop\Tailwind\Ranjith_Portfolio\env\Lib\site-packages\django\contrib\sessions\backends\db.py", line 55, in load
    s = self._get_session_from_db()
  File "C:\Users\hp\OneDrive\Desktop\Tailwind\Ranjith_Portfolio\env\Lib\site-packages\django\contrib\sessions\backends\db.py", line 34, in _get_session_from_db
    return self.model.objects.get(
           ~~~~~~~~~~~~~~~~~~~~~~^
        session_key=self.session_key, expire_date__gt=timezone.now()
        ^^^^^^^^^^^^^^^^^^^^^^^^^^^^^^^^^^^^^^^^^^^^^^^^^^^^^^^^^^^^
    )
    ^
  File "C:\Users\hp\OneDrive\Desktop\Tailwind\Ranjith_Portfolio\env\Lib\site-packages\django\db\models\manager.py", line 87, in manager_method
    return getattr(self.get_queryset(), name)(*args, **kwargs)
           ~~~~~~~~~~~~~~~~~~~~~~~~~~~~~~~~~~^^^^^^^^^^^^^^^^^
  File "C:\Users\hp\OneDrive\Desktop\Tailwind\Ranjith_Portfolio\env\Lib\site-packages\django\db\models\query.py", line 629, in get
    num = len(clone)
  File "C:\Users\hp\OneDrive\Desktop\Tailwind\Ranjith_Portfolio\env\Lib\site-packages\django\db\models\query.py", line 366, in __len__
    self._fetch_all()
    ~~~~~~~~~~~~~~~^^
  File "C:\Users\hp\OneDrive\Desktop\Tailwind\Ranjith_Portfolio\env\Lib\site-packages\django\db\models\query.py", line 1949, in _fetch_all
    self._result_cache = list(self._iterable_class(self))
                         ~~~~^^^^^^^^^^^^^^^^^^^^^^^^^^^^
  File "C:\Users\hp\OneDrive\Desktop\Tailwind\Ranjith_Portfolio\env\Lib\site-packages\django\db\models\query.py", line 91, in __iter__
    results = compiler.execute_sql(
        chunked_fetch=self.chunked_fetch, chunk_size=self.chunk_size
    )
  File "C:\Users\hp\OneDrive\Desktop\Tailwind\Ranjith_Portfolio\env\Lib\site-packages\django\db\models\sql\compiler.py", line 1623, in execute_sql
    cursor.execute(sql, params)
    ~~~~~~~~~~~~~~^^^^^^^^^^^^^
  File "C:\Users\hp\OneDrive\Desktop\Tailwind\Ranjith_Portfolio\env\Lib\site-packages\django\db\backends\utils.py", line 122, in execute
    return super().execute(sql, params)
           ~~~~~~~~~~~~~~~^^^^^^^^^^^^^
  File "C:\Users\hp\OneDrive\Desktop\Tailwind\Ranjith_Portfolio\env\Lib\site-packages\django\db\backends\utils.py", line 79, in execute
    return self._execute_with_wrappers(
           ~~~~~~~~~~~~~~~~~~~~~~~~~~~^
        sql, params, many=False, executor=self._execute
        ^^^^^^^^^^^^^^^^^^^^^^^^^^^^^^^^^^^^^^^^^^^^^^^
    )
    ^
  File "C:\Users\hp\OneDrive\Desktop\Tailwind\Ranjith_Portfolio\env\Lib\site-packages\django\db\backends\utils.py", line 92, in _execute_with_wrappers
    return executor(sql, params, many, context)
  File "C:\Users\hp\OneDrive\Desktop\Tailwind\Ranjith_Portfolio\env\Lib\site-packages\django\db\backends\utils.py", line 100, in _execute
    with self.db.wrap_database_errors:
         ^^^^^^^^^^^^^^^^^^^^^^^^^^^^
  File "C:\Users\hp\OneDrive\Desktop\Tailwind\Ranjith_Portfolio\env\Lib\site-packages\django\db\utils.py", line 91, in __exit__
    raise dj_exc_value.with_traceback(traceback) from exc_value
  File "C:\Users\hp\OneDrive\Desktop\Tailwind\Ranjith_Portfolio\env\Lib\site-packages\django\db\backends\utils.py", line 105, in _execute
    return self.cursor.execute(sql, params)
           ~~~~~~~~~~~~~~~~~~~^^^^^^^^^^^^^
  File "C:\Users\hp\OneDrive\Desktop\Tailwind\Ranjith_Portfolio\env\Lib\site-packages\django\db\backends\sqlite3\base.py", line 360, in execute
    return super().execute(query, params)
           ~~~~~~~~~~~~~~~^^^^^^^^^^^^^^^
django.db.utils.OperationalError: no such table: django_session
ERROR 2025-07-06 13:43:23,484 basehttp 9220 15784 "GET /admin/portfolio/skill/add/ HTTP/1.1" 500 209738
ERROR 2025-07-06 13:43:32,384 log 9220 15784 Internal Server Error: /admin/
Traceback (most recent call last):
  File "C:\Users\hp\OneDrive\Desktop\Tailwind\Ranjith_Portfolio\env\Lib\site-packages\django\contrib\sessions\backends\base.py", line 244, in _get_session
    return self._session_cache
           ^^^^^^^^^^^^^^^^^^^
AttributeError: 'SessionStore' object has no attribute '_session_cache'

During handling of the above exception, another exception occurred:

Traceback (most recent call last):
  File "C:\Users\hp\OneDrive\Desktop\Tailwind\Ranjith_Portfolio\env\Lib\site-packages\django\db\backends\utils.py", line 105, in _execute
    return self.cursor.execute(sql, params)
           ~~~~~~~~~~~~~~~~~~~^^^^^^^^^^^^^
  File "C:\Users\hp\OneDrive\Desktop\Tailwind\Ranjith_Portfolio\env\Lib\site-packages\django\db\backends\sqlite3\base.py", line 360, in execute
    return super().execute(query, params)
           ~~~~~~~~~~~~~~~^^^^^^^^^^^^^^^
sqlite3.OperationalError: no such table: django_session

The above exception was the direct cause of the following exception:

Traceback (most recent call last):
  File "C:\Users\hp\OneDrive\Desktop\Tailwind\Ranjith_Portfolio\env\Lib\site-packages\django\core\handlers\exception.py", line 55, in inner
    response = get_response(request)
  File "C:\Users\hp\OneDrive\Desktop\Tailwind\Ranjith_Portfolio\env\Lib\site-packages\django\core\handlers\base.py", line 197, in _get_response
    response = wrapped_callback(request, *callback_args, **callback_kwargs)
  File "C:\Users\hp\OneDrive\Desktop\Tailwind\Ranjith_Portfolio\env\Lib\site-packages\django\contrib\admin\sites.py", line 265, in wrapper
    return self.admin_view(view, cacheable)(*args, **kwargs)
           ~~~~~~~~~~~~~~~~~~~~~~~~~~~~~~~~^^^^^^^^^^^^^^^^^
  File "C:\Users\hp\OneDrive\Desktop\Tailwind\Ranjith_Portfolio\env\Lib\site-packages\django\utils\decorators.py", line 192, in _view_wrapper
    result = _process_exception(request, e)
  File "C:\Users\hp\OneDrive\Desktop\Tailwind\Ranjith_Portfolio\env\Lib\site-packages\django\utils\decorators.py", line 190, in _view_wrapper
    response = view_func(request, *args, **kwargs)
  File "C:\Users\hp\OneDrive\Desktop\Tailwind\Ranjith_Portfolio\env\Lib\site-packages\django\views\decorators\cache.py", line 80, in _view_wrapper
    response = view_func(request, *args, **kwargs)
  File "C:\Users\hp\OneDrive\Desktop\Tailwind\Ranjith_Portfolio\env\Lib\site-packages\django\contrib\admin\sites.py", line 234, in inner
    if not self.has_permission(request):
           ~~~~~~~~~~~~~~~~~~~^^^^^^^^^
  File "C:\Users\hp\OneDrive\Desktop\Tailwind\Ranjith_Portfolio\env\Lib\site-packages\django\contrib\admin\sites.py", line 207, in has_permission
    return request.user.is_active and request.user.is_staff
           ^^^^^^^^^^^^^^^^^^^^^^
  File "C:\Users\hp\OneDrive\Desktop\Tailwind\Ranjith_Portfolio\env\Lib\site-packages\django\utils\functional.py", line 251, in inner
    self._setup()
    ~~~~~~~~~~~^^
  File "C:\Users\hp\OneDrive\Desktop\Tailwind\Ranjith_Portfolio\env\Lib\site-packages\django\utils\functional.py", line 404, in _setup
    self._wrapped = self._setupfunc()
                    ~~~~~~~~~~~~~~~^^
  File "C:\Users\hp\OneDrive\Desktop\Tailwind\Ranjith_Portfolio\env\Lib\site-packages\django\contrib\auth\middleware.py", line 40, in <lambda>
    request.user = SimpleLazyObject(lambda: get_user(request))
                                            ~~~~~~~~^^^^^^^^^
  File "C:\Users\hp\OneDrive\Desktop\Tailwind\Ranjith_Portfolio\env\Lib\site-packages\django\contrib\auth\middleware.py", line 20, in get_user
    request._cached_user = auth.get_user(request)
                           ~~~~~~~~~~~~~^^^^^^^^^
  File "C:\Users\hp\OneDrive\Desktop\Tailwind\Ranjith_Portfolio\env\Lib\site-packages\django\contrib\auth\__init__.py", line 304, in get_user
    user_id = _get_user_session_key(request)
  File "C:\Users\hp\OneDrive\Desktop\Tailwind\Ranjith_Portfolio\env\Lib\site-packages\django\contrib\auth\__init__.py", line 95, in _get_user_session_key
    return get_user_model()._meta.pk.to_python(request.session[SESSION_KEY])
                                               ~~~~~~~~~~~~~~~^^^^^^^^^^^^^
  File "C:\Users\hp\OneDrive\Desktop\Tailwind\Ranjith_Portfolio\env\Lib\site-packages\django\contrib\sessions\backends\base.py", line 55, in __getitem__
    return self._session[key]
           ^^^^^^^^^^^^^
  File "C:\Users\hp\OneDrive\Desktop\Tailwind\Ranjith_Portfolio\env\Lib\site-packages\django\contrib\sessions\backends\base.py", line 249, in _get_session
    self._session_cache = self.load()
                          ~~~~~~~~~^^
  File "C:\Users\hp\OneDrive\Desktop\Tailwind\Ranjith_Portfolio\env\Lib\site-packages\django\contrib\sessions\backends\db.py", line 55, in load
    s = self._get_session_from_db()
  File "C:\Users\hp\OneDrive\Desktop\Tailwind\Ranjith_Portfolio\env\Lib\site-packages\django\contrib\sessions\backends\db.py", line 34, in _get_session_from_db
    return self.model.objects.get(
           ~~~~~~~~~~~~~~~~~~~~~~^
        session_key=self.session_key, expire_date__gt=timezone.now()
        ^^^^^^^^^^^^^^^^^^^^^^^^^^^^^^^^^^^^^^^^^^^^^^^^^^^^^^^^^^^^
    )
    ^
  File "C:\Users\hp\OneDrive\Desktop\Tailwind\Ranjith_Portfolio\env\Lib\site-packages\django\db\models\manager.py", line 87, in manager_method
    return getattr(self.get_queryset(), name)(*args, **kwargs)
           ~~~~~~~~~~~~~~~~~~~~~~~~~~~~~~~~~~^^^^^^^^^^^^^^^^^
  File "C:\Users\hp\OneDrive\Desktop\Tailwind\Ranjith_Portfolio\env\Lib\site-packages\django\db\models\query.py", line 629, in get
    num = len(clone)
  File "C:\Users\hp\OneDrive\Desktop\Tailwind\Ranjith_Portfolio\env\Lib\site-packages\django\db\models\query.py", line 366, in __len__
    self._fetch_all()
    ~~~~~~~~~~~~~~~^^
  File "C:\Users\hp\OneDrive\Desktop\Tailwind\Ranjith_Portfolio\env\Lib\site-packages\django\db\models\query.py", line 1949, in _fetch_all
    self._result_cache = list(self._iterable_class(self))
                         ~~~~^^^^^^^^^^^^^^^^^^^^^^^^^^^^
  File "C:\Users\hp\OneDrive\Desktop\Tailwind\Ranjith_Portfolio\env\Lib\site-packages\django\db\models\query.py", line 91, in __iter__
    results = compiler.execute_sql(
        chunked_fetch=self.chunked_fetch, chunk_size=self.chunk_size
    )
  File "C:\Users\hp\OneDrive\Desktop\Tailwind\Ranjith_Portfolio\env\Lib\site-packages\django\db\models\sql\compiler.py", line 1623, in execute_sql
    cursor.execute(sql, params)
    ~~~~~~~~~~~~~~^^^^^^^^^^^^^
  File "C:\Users\hp\OneDrive\Desktop\Tailwind\Ranjith_Portfolio\env\Lib\site-packages\django\db\backends\utils.py", line 122, in execute
    return super().execute(sql, params)
           ~~~~~~~~~~~~~~~^^^^^^^^^^^^^
  File "C:\Users\hp\OneDrive\Desktop\Tailwind\Ranjith_Portfolio\env\Lib\site-packages\django\db\backends\utils.py", line 79, in execute
    return self._execute_with_wrappers(
           ~~~~~~~~~~~~~~~~~~~~~~~~~~~^
        sql, params, many=False, executor=self._execute
        ^^^^^^^^^^^^^^^^^^^^^^^^^^^^^^^^^^^^^^^^^^^^^^^
    )
    ^
  File "C:\Users\hp\OneDrive\Desktop\Tailwind\Ranjith_Portfolio\env\Lib\site-packages\django\db\backends\utils.py", line 92, in _execute_with_wrappers
    return executor(sql, params, many, context)
  File "C:\Users\hp\OneDrive\Desktop\Tailwind\Ranjith_Portfolio\env\Lib\site-packages\django\db\backends\utils.py", line 100, in _execute
    with self.db.wrap_database_errors:
         ^^^^^^^^^^^^^^^^^^^^^^^^^^^^
  File "C:\Users\hp\OneDrive\Desktop\Tailwind\Ranjith_Portfolio\env\Lib\site-packages\django\db\utils.py", line 91, in __exit__
    raise dj_exc_value.with_traceback(traceback) from exc_value
  File "C:\Users\hp\OneDrive\Desktop\Tailwind\Ranjith_Portfolio\env\Lib\site-packages\django\db\backends\utils.py", line 105, in _execute
    return self.cursor.execute(sql, params)
           ~~~~~~~~~~~~~~~~~~~^^^^^^^^^^^^^
  File "C:\Users\hp\OneDrive\Desktop\Tailwind\Ranjith_Portfolio\env\Lib\site-packages\django\db\backends\sqlite3\base.py", line 360, in execute
    return super().execute(query, params)
           ~~~~~~~~~~~~~~~^^^^^^^^^^^^^^^
django.db.utils.OperationalError: no such table: django_session
ERROR 2025-07-06 13:43:32,405 basehttp 9220 15784 "GET /admin/ HTTP/1.1" 500 209356
ERROR 2025-07-06 13:43:37,122 log 9220 15784 Internal Server Error: /admin/
Traceback (most recent call last):
  File "C:\Users\hp\OneDrive\Desktop\Tailwind\Ranjith_Portfolio\env\Lib\site-packages\django\contrib\sessions\backends\base.py", line 244, in _get_session
    return self._session_cache
           ^^^^^^^^^^^^^^^^^^^
AttributeError: 'SessionStore' object has no attribute '_session_cache'

During handling of the above exception, another exception occurred:

Traceback (most recent call last):
  File "C:\Users\hp\OneDrive\Desktop\Tailwind\Ranjith_Portfolio\env\Lib\site-packages\django\db\backends\utils.py", line 105, in _execute
    return self.cursor.execute(sql, params)
           ~~~~~~~~~~~~~~~~~~~^^^^^^^^^^^^^
  File "C:\Users\hp\OneDrive\Desktop\Tailwind\Ranjith_Portfolio\env\Lib\site-packages\django\db\backends\sqlite3\base.py", line 360, in execute
    return super().execute(query, params)
           ~~~~~~~~~~~~~~~^^^^^^^^^^^^^^^
sqlite3.OperationalError: no such table: django_session

The above exception was the direct cause of the following exception:

Traceback (most recent call last):
  File "C:\Users\hp\OneDrive\Desktop\Tailwind\Ranjith_Portfolio\env\Lib\site-packages\django\core\handlers\exception.py", line 55, in inner
    response = get_response(request)
  File "C:\Users\hp\OneDrive\Desktop\Tailwind\Ranjith_Portfolio\env\Lib\site-packages\django\core\handlers\base.py", line 197, in _get_response
    response = wrapped_callback(request, *callback_args, **callback_kwargs)
  File "C:\Users\hp\OneDrive\Desktop\Tailwind\Ranjith_Portfolio\env\Lib\site-packages\django\contrib\admin\sites.py", line 265, in wrapper
    return self.admin_view(view, cacheable)(*args, **kwargs)
           ~~~~~~~~~~~~~~~~~~~~~~~~~~~~~~~~^^^^^^^^^^^^^^^^^
  File "C:\Users\hp\OneDrive\Desktop\Tailwind\Ranjith_Portfolio\env\Lib\site-packages\django\utils\decorators.py", line 192, in _view_wrapper
    result = _process_exception(request, e)
  File "C:\Users\hp\OneDrive\Desktop\Tailwind\Ranjith_Portfolio\env\Lib\site-packages\django\utils\decorators.py", line 190, in _view_wrapper
    response = view_func(request, *args, **kwargs)
  File "C:\Users\hp\OneDrive\Desktop\Tailwind\Ranjith_Portfolio\env\Lib\site-packages\django\views\decorators\cache.py", line 80, in _view_wrapper
    response = view_func(request, *args, **kwargs)
  File "C:\Users\hp\OneDrive\Desktop\Tailwind\Ranjith_Portfolio\env\Lib\site-packages\django\contrib\admin\sites.py", line 234, in inner
    if not self.has_permission(request):
           ~~~~~~~~~~~~~~~~~~~^^^^^^^^^
  File "C:\Users\hp\OneDrive\Desktop\Tailwind\Ranjith_Portfolio\env\Lib\site-packages\django\contrib\admin\sites.py", line 207, in has_permission
    return request.user.is_active and request.user.is_staff
           ^^^^^^^^^^^^^^^^^^^^^^
  File "C:\Users\hp\OneDrive\Desktop\Tailwind\Ranjith_Portfolio\env\Lib\site-packages\django\utils\functional.py", line 251, in inner
    self._setup()
    ~~~~~~~~~~~^^
  File "C:\Users\hp\OneDrive\Desktop\Tailwind\Ranjith_Portfolio\env\Lib\site-packages\django\utils\functional.py", line 404, in _setup
    self._wrapped = self._setupfunc()
                    ~~~~~~~~~~~~~~~^^
  File "C:\Users\hp\OneDrive\Desktop\Tailwind\Ranjith_Portfolio\env\Lib\site-packages\django\contrib\auth\middleware.py", line 40, in <lambda>
    request.user = SimpleLazyObject(lambda: get_user(request))
                                            ~~~~~~~~^^^^^^^^^
  File "C:\Users\hp\OneDrive\Desktop\Tailwind\Ranjith_Portfolio\env\Lib\site-packages\django\contrib\auth\middleware.py", line 20, in get_user
    request._cached_user = auth.get_user(request)
                           ~~~~~~~~~~~~~^^^^^^^^^
  File "C:\Users\hp\OneDrive\Desktop\Tailwind\Ranjith_Portfolio\env\Lib\site-packages\django\contrib\auth\__init__.py", line 304, in get_user
    user_id = _get_user_session_key(request)
  File "C:\Users\hp\OneDrive\Desktop\Tailwind\Ranjith_Portfolio\env\Lib\site-packages\django\contrib\auth\__init__.py", line 95, in _get_user_session_key
    return get_user_model()._meta.pk.to_python(request.session[SESSION_KEY])
                                               ~~~~~~~~~~~~~~~^^^^^^^^^^^^^
  File "C:\Users\hp\OneDrive\Desktop\Tailwind\Ranjith_Portfolio\env\Lib\site-packages\django\contrib\sessions\backends\base.py", line 55, in __getitem__
    return self._session[key]
           ^^^^^^^^^^^^^
  File "C:\Users\hp\OneDrive\Desktop\Tailwind\Ranjith_Portfolio\env\Lib\site-packages\django\contrib\sessions\backends\base.py", line 249, in _get_session
    self._session_cache = self.load()
                          ~~~~~~~~~^^
  File "C:\Users\hp\OneDrive\Desktop\Tailwind\Ranjith_Portfolio\env\Lib\site-packages\django\contrib\sessions\backends\db.py", line 55, in load
    s = self._get_session_from_db()
  File "C:\Users\hp\OneDrive\Desktop\Tailwind\Ranjith_Portfolio\env\Lib\site-packages\django\contrib\sessions\backends\db.py", line 34, in _get_session_from_db
    return self.model.objects.get(
           ~~~~~~~~~~~~~~~~~~~~~~^
        session_key=self.session_key, expire_date__gt=timezone.now()
        ^^^^^^^^^^^^^^^^^^^^^^^^^^^^^^^^^^^^^^^^^^^^^^^^^^^^^^^^^^^^
    )
    ^
  File "C:\Users\hp\OneDrive\Desktop\Tailwind\Ranjith_Portfolio\env\Lib\site-packages\django\db\models\manager.py", line 87, in manager_method
    return getattr(self.get_queryset(), name)(*args, **kwargs)
           ~~~~~~~~~~~~~~~~~~~~~~~~~~~~~~~~~~^^^^^^^^^^^^^^^^^
  File "C:\Users\hp\OneDrive\Desktop\Tailwind\Ranjith_Portfolio\env\Lib\site-packages\django\db\models\query.py", line 629, in get
    num = len(clone)
  File "C:\Users\hp\OneDrive\Desktop\Tailwind\Ranjith_Portfolio\env\Lib\site-packages\django\db\models\query.py", line 366, in __len__
    self._fetch_all()
    ~~~~~~~~~~~~~~~^^
  File "C:\Users\hp\OneDrive\Desktop\Tailwind\Ranjith_Portfolio\env\Lib\site-packages\django\db\models\query.py", line 1949, in _fetch_all
    self._result_cache = list(self._iterable_class(self))
                         ~~~~^^^^^^^^^^^^^^^^^^^^^^^^^^^^
  File "C:\Users\hp\OneDrive\Desktop\Tailwind\Ranjith_Portfolio\env\Lib\site-packages\django\db\models\query.py", line 91, in __iter__
    results = compiler.execute_sql(
        chunked_fetch=self.chunked_fetch, chunk_size=self.chunk_size
    )
  File "C:\Users\hp\OneDrive\Desktop\Tailwind\Ranjith_Portfolio\env\Lib\site-packages\django\db\models\sql\compiler.py", line 1623, in execute_sql
    cursor.execute(sql, params)
    ~~~~~~~~~~~~~~^^^^^^^^^^^^^
  File "C:\Users\hp\OneDrive\Desktop\Tailwind\Ranjith_Portfolio\env\Lib\site-packages\django\db\backends\utils.py", line 122, in execute
    return super().execute(sql, params)
           ~~~~~~~~~~~~~~~^^^^^^^^^^^^^
  File "C:\Users\hp\OneDrive\Desktop\Tailwind\Ranjith_Portfolio\env\Lib\site-packages\django\db\backends\utils.py", line 79, in execute
    return self._execute_with_wrappers(
           ~~~~~~~~~~~~~~~~~~~~~~~~~~~^
        sql, params, many=False, executor=self._execute
        ^^^^^^^^^^^^^^^^^^^^^^^^^^^^^^^^^^^^^^^^^^^^^^^
    )
    ^
  File "C:\Users\hp\OneDrive\Desktop\Tailwind\Ranjith_Portfolio\env\Lib\site-packages\django\db\backends\utils.py", line 92, in _execute_with_wrappers
    return executor(sql, params, many, context)
  File "C:\Users\hp\OneDrive\Desktop\Tailwind\Ranjith_Portfolio\env\Lib\site-packages\django\db\backends\utils.py", line 100, in _execute
    with self.db.wrap_database_errors:
         ^^^^^^^^^^^^^^^^^^^^^^^^^^^^
  File "C:\Users\hp\OneDrive\Desktop\Tailwind\Ranjith_Portfolio\env\Lib\site-packages\django\db\utils.py", line 91, in __exit__
    raise dj_exc_value.with_traceback(traceback) from exc_value
  File "C:\Users\hp\OneDrive\Desktop\Tailwind\Ranjith_Portfolio\env\Lib\site-packages\django\db\backends\utils.py", line 105, in _execute
    return self.cursor.execute(sql, params)
           ~~~~~~~~~~~~~~~~~~~^^^^^^^^^^^^^
  File "C:\Users\hp\OneDrive\Desktop\Tailwind\Ranjith_Portfolio\env\Lib\site-packages\django\db\backends\sqlite3\base.py", line 360, in execute
    return super().execute(query, params)
           ~~~~~~~~~~~~~~~^^^^^^^^^^^^^^^
django.db.utils.OperationalError: no such table: django_session
ERROR 2025-07-06 13:43:37,148 basehttp 9220 15784 "GET /admin/ HTTP/1.1" 500 209356
INFO 2025-07-06 13:47:04,453 autoreload 9220 25408 C:\Users\hp\OneDrive\Desktop\Tailwind\Ranjith_Portfolio\Ranjith_Portfolio\settings.py changed, reloading.
INFO 2025-07-06 13:47:06,726 autoreload 21260 13784 Watching for file changes with StatReloader
INFO 2025-07-06 13:47:09,787 autoreload 21260 13784 C:\Users\hp\OneDrive\Desktop\Tailwind\Ranjith_Portfolio\Ranjith_Portfolio\settings.py changed, reloading.
INFO 2025-07-06 13:47:12,269 autoreload 17784 14200 Watching for file changes with StatReloader
INFO 2025-07-06 13:47:15,218 autoreload 17784 14200 C:\Users\hp\OneDrive\Desktop\Tailwind\Ranjith_Portfolio\Ranjith_Portfolio\settings.py changed, reloading.
INFO 2025-07-06 13:47:17,470 autoreload 16360 22392 Watching for file changes with StatReloader
ERROR 2025-07-06 13:51:22,234 log 20692 21104 Invalid HTTP_HOST header: 'testserver'. You may need to add 'testserver' to ALLOWED_HOSTS.
Traceback (most recent call last):
  File "C:\Users\hp\OneDrive\Desktop\Tailwind\Ranjith_Portfolio\env\Lib\site-packages\django\core\handlers\exception.py", line 55, in inner
    response = get_response(request)
  File "C:\Users\hp\OneDrive\Desktop\Tailwind\Ranjith_Portfolio\env\Lib\site-packages\django\utils\deprecation.py", line 119, in __call__
    response = self.process_request(request)
  File "C:\Users\hp\OneDrive\Desktop\Tailwind\Ranjith_Portfolio\env\Lib\site-packages\django\middleware\common.py", line 48, in process_request
    host = request.get_host()
  File "C:\Users\hp\OneDrive\Desktop\Tailwind\Ranjith_Portfolio\env\Lib\site-packages\django\http\request.py", line 202, in get_host
    raise DisallowedHost(msg)
django.core.exceptions.DisallowedHost: Invalid HTTP_HOST header: 'testserver'. You may need to add 'testserver' to ALLOWED_HOSTS.
INFO 2025-07-06 13:56:53,464 autoreload 16360 22392 C:\Users\hp\OneDrive\Desktop\Tailwind\Ranjith_Portfolio\Ranjith_Portfolio\settings.py changed, reloading.
INFO 2025-07-06 14:03:41,891 autoreload 9388 9048 Watching for file changes with StatReloader
INFO 2025-07-06 15:17:33,674 autoreload 13468 23624 Watching for file changes with StatReloader
